Workbook

Sheet Fiche de production
A1: Fiche de production Cuve de 7000 L | I1: Code : PROD_EN_002
I2: Version : 07
I3: Création : 20/07/2021
I4: Mis à jour : 14/10/2025
A6: Produit préparé
A8: Produit :
A10: DDM : | H10: LOT | I10: =B10 -> 0
B12: 33 CL | F12: 75 CL
B13: SYMBIOSE | D13: NIKO | E13: INTER | F13: SYMBIOSE | H13: NIKO | I13: AUTRE
A14: Quantité | B14: X12 | C14: X6 | D14: X12 | E14: X6 | F14: X6 | G14: X4 | H14: X6
A15: Bouteilles | B15: =B16*12 -> 0 | C15: =C16*6 -> 0 | D15: =D16*12 -> 0 | E15: =E16*6 -> 0 | F15: =F16*6 -> 0 | G15: =G16*4 -> 0 | H15: =H16*6 -> 0
A16: Cartons
A17: Volume (L) | B17: =(SUM(B15:E15)*0.33+SUM(F15:I15)*0.75) -> 0
A19: Fermentation
A20: Date | B20: Heure | C20: Brix | D20: PH | E20: °C | F20: Goût | G20: Observation | J20: Matricule
F21: OK/NOK
F22: OK/NOK
F23: OK/NOK
F24: OK/NOK
A26: Fermentation : | D26: Conforme
D27: Non conforme
A29: Phase 1 : DILUTION | G29: Emballage
A30: Sucre (kg) | C30: =_xlfn.XLOOKUP(_xlfn.XLOOKUP(B8,Data!A:A,Data!B:B),Recettes!B:B,Recettes!C:C) -> 0 | G30: Désignation | I30: Unité | J30: Palette
A31: Figues (kg) | C31: =_xlfn.XLOOKUP(_xlfn.XLOOKUP(B8,Data!A:A,Data!B:B),Recettes!B:B,Recettes!D:D) -> 0 | G31: Bavarian 33cl | I31: =SUM(B15:E15) -> 0 | J31: =I31/3610 -> 0
A32: Jus de Citron (kg) | C32: =_xlfn.XLOOKUP(_xlfn.XLOOKUP(B8,Data!A:A,Data!B:B),Recettes!B:B,Recettes!E:E) -> 0 | G32: Saft 75cl | I32: =G15+H15 -> 0 | J32: =I32/1421 -> 0
A33: Grains (kg) | C33: =_xlfn.XLOOKUP(_xlfn.XLOOKUP(B8,Data!A:A,Data!B:B),Recettes!B:B,Recettes!F:F) -> 0 | G33: Eau gazeuse 75cl | I33: =F15 -> 0 | J33: =I33/1421 -> 0
A35: Volume de remplissage : | C35: =B17+800 -> 800 | G35: Palette Europe | I35: =F17 -> 0 | J35: =I35/1421 -> 0
A36: Niveau de liquide : | C36: ='CUVE 3 et 4 Mesure'!G6 -> #DIV/0!
A37: Pression sur le bulleur : | C37: 3 bars
A38: Température de cuve : | C38: 24°C
A40: Phase 2 : Filtration
A41: =A8 -> Produit :
A42: Volume filtré : | B42: =IF(ISNUMBER( SEARCH("Infusion",B8)), 0, (C35-400)*60%) -> 240
A43: Volume final : | B43: =IF(ISNUMBER(SEARCH("infusion",B8)),0,_xlfn.XLOOKUP(B8,Data!E:E,Data!F:F)*'Fiche de production'!C35+B42) -> 240
A44: Hauteur : | B44: ='CUVE 3 et 4 Mesure'!G13 -> 15.52
A46: Phase 2 : Remplissage
A47: =A14 -> Quantité
A48: Volume total : | B48: =_xlfn.XLOOKUP(B8,Data!E:E,Data!F:F)*'Fiche de production'!C35+C35-400 -> 400
A49: Hauteur : | B49: ='CUVE 3 et 4 Mesure'!G21 -> #DIV/0!
A51: IMPORTANT : la hauteur totale prend en compte l'ajout des jus de l'aromatisation
...

Sheet Recettes
A1: Quantité (L) | B1: ='Fiche de production'!C35 -> 800
C3: Sucre (kg) | D3: Figues (kg) | E3: Jus de Citron (kg) | F3: Grains (kg)
B4: Infusion | C4: =B12*B1 -> 8.8 | D4: =B1*B13 -> 6.4 | E4: =B14*B1 -> 3.2 | F4: =B15*B1 -> 6.4
B5: Kéfir | C5: =B1*B21 -> 28 | D5: =B1*B22 -> 12.8 | E5: =B23*B1 -> 3.2 | F5: =B24*B1 -> 4.8
A10: Recette Eau
B11: Facteur 1L
A12: sucre blanc | B12: 0.011
A13: figues | B13: 0.008
A14: jus citron | B14: 0.004
A15: grain | B15: 0.008
A19: Recette Kefir
B20: Facteur 1L
A21: sucre blanc | B21: 0.035
A22: figues | B22: 0.016
A23: jus citron | B23: 0.004
A24: grain | B24: 0.006

Sheet Data
A1: Produit 1 | B1: Type | C1: DDM | E1: Ajouts de Jus / L | F1: pour 1L
A2: K. Original | B2: Kéfir | C2: 365 | E2: K. Original | F2: 0.004
A3: K. Menthe - Citron Vert | B3: Kéfir | C3: 365 | E3: K. Menthe - Citron Vert | F3: 0.008
A4: K. Gingembre | B4: Kéfir | C4: 365 | E4: K. Gingembre | F4: 0.024
A5: K. Pamplemousse | B5: Kéfir | C5: 365 | E5: K. Pamplemousse | F5: =0.08+0.0012+0.004 -> 0.0852
A6: K. Mangue - Passion | B6: Kéfir | C6: 365 | E6: K. Mangue - Passion | F6: 0.034
A7: Infusion Menthe Poivrée | B7: infusion | C7: 365 | E7: Infusion Menthe Poivrée | F7: 0.0047
A8: Infusion Mélisse | B8: infusion | C8: 365 | E8: Infusion Mélisse | F8: 0.007
A9: Infusion Zest d'agrumes | B9: infusion | C9: 365 | E9: Infusion Zest d'agrumes | F9: 0
A10: K. Pêche | B10: Kéfir | C10: 365 | E10: K. Pêche | F10: 0.0158
A11: Autre : | C11: 365

Sheet CUVE 3 et 4 Mesure
A1: Volume (L) | B1: Hauteur (cm) | F1: Volume de remplissage | G1: ='Fiche de production'!C35 -> 800
A2: 50 | B2: 3.3 | F2: Limite Basse | G2: {=MAX(IF(A:A<=G1,A:A))} -> 800
A3: 100 | B3: 7.5 | F3: Limite Haute | G3: {=MIN(IF(A:A>=G1,A:A))} -> 800
A4: 150 | B4: 10.8 | F4: Hauteur limite Basse | G4: =_xlfn.XLOOKUP(G2,A:A,B:B) -> 36
A5: 200 | B5: 13.6 | F5: Hauteur limite Haute | G5: =_xlfn.XLOOKUP(G3,A:A,B:B) -> 36
A6: 250 | B6: 16 | F6: HAUTEUR CIBLE | G6: =G4+(G1-G2)*(G5-G4)/(G3-G2) -> #DIV/0!
A7: 300 | B7: 18.2
A8: 350 | B8: 20.4 | F8: Valeur recherchée Produit Post Filtration | G8: ='Fiche de production'!B43 -> 240
A9: 400 | B9: 22.4 | F9: Limite Basse | G9: {=MAX(IF(A:A<=G8,A:A))} -> 200
A10: 428.57143 | B10: 24 | F10: Limite Haute | G10: {=MIN(IF(A:A>=G8,A:A))} -> 250
A11: 450 | B11: 24.3 | F11: Hauteur limite Basse | G11: =_xlfn.XLOOKUP(G9,A:A,B:B) -> 13.6
A12: 500 | B12: 26 | F12: Hauteur limite Haute | G12: =_xlfn.XLOOKUP(G10,A:A,B:B) -> 16
A13: 550 | B13: 27.5 | F13: HAUTEUR CIBLE | G13: =IFERROR((G11+(G8-G9)*(G12-G11)/(G10-G9)),0) -> 15.52
A14: 600 | B14: 29.2
A15: 650 | B15: 30.9
A16: 700 | B16: 32.7 | F16: Valeur recherchée Produit Cuve pleine | G16: ='Fiche de production'!B48 -> 400
A17: 750 | B17: 34.5 | F17: Limite Basse | G17: {=MAX(IF(A:A<=G16,A:A))} -> 400
A18: 800 | B18: 36 | F18: Limite Haute | G18: {=MIN(IF(A:A>=G16,A:A))} -> 400
A19: 850 | B19: 37.6 | F19: Hauteur limite Basse | G19: =_xlfn.XLOOKUP(G17,A:A,B:B) -> 22.4
A20: 900 | B20: 39.3 | F20: Hauteur limite Haute | G20: =_xlfn.XLOOKUP(G18,A:A,B:B) -> 22.4
A21: 950 | B21: 41 | F21: HAUTEUR CIBLE | G21: =G19+(G16-G17)*(G20-G19)/(G18-G17) -> #DIV/0!
A22: 1000 | B22: 42.5
A23: 1050 | B23: 43.8
A24: 1100 | B24: 45
A25: 1150 | B25: 46.6
A26: 1200 | B26: 48.274214
A27: 1250 | B27: 49.948427
A28: 1300 | B28: 51.622641
A29: 1350 | B29: 53.296855
A30: 1400 | B30: 54.971069
A31: 1450 | B31: 56.645282
A32: 1500 | B32: 58.319496
A33: 1550 | B33: 59.99371
... A148: 7250 | B148: 250.85408
