Workbook

Sheet Fiche de production
A1: Fiche de production Cuve de 5000 L | I1: Code : PROD_EN_002
I2: Version : 07
I3: Création : 20/07/2021
I4: Mis à jour : 14/10/2025
A6: Produit préparé
A8: Produit : | B8: K. Gingembre
A10: DDM : | B10: 46427 | H10: LOT | I10: 90226
B12: 33 CL | F12: 75 CL
B13: SYMBIOSE | D13: NIKO | E13: INTER | F13: SYMBIOSE | H13: NIKO | I13: AUTRE
A14: Quantité | B14: X12 | C14: X6 | D14: X12 | E14: X6 | F14: X6 | G14: X4 | H14: X6
A15: Bouteilles | B15: =B16*12 -> 12 | C15: =C16*6 -> 2400 | D15: =D16*12 -> 6000 | E15: =E16*6 -> 3600 | F15: =F16*6 -> 6 | G15: =G16*4 -> 1104 | H15: =H16*6 -> 6
A16: Cartons | B16: 1 | C16: 400 | D16: 500 | E16: 600 | F16: 1 | G16: 276 | H16: 1
A17: Volume (L) | B17: =(SUM(B15:E15)*0.33+SUM(F15:I15)*0.75) -> 4800.96
A19: Fermentation
A20: Date | B20: Heure | C20: Brix | D20: PH | E20: °C | F20: Goût | G20: Observation | J20: Matricule
A21: 46062 | F21: OK/NOK
F22: OK/NOK
F23: OK/NOK
F24: OK/NOK
A26: Fermentation : | C26: FALSE | D26: Conforme
C27: FALSE | D27: Non conforme
A29: Phase 1 : DILUTION | G29: Emballage
A30: Sucre (kg) | C30: =_xlfn.XLOOKUP(_xlfn.XLOOKUP(B8,Data!A:A,Data!B:B),Recettes!B:B,Recettes!C:C) -> 182.0336 | G30: Désignation | I30: Unité | J30: Palette
A31: Figues (kg) | C31: =_xlfn.XLOOKUP(_xlfn.XLOOKUP(B8,Data!A:A,Data!B:B),Recettes!B:B,Recettes!D:D) -> 83.21536 | G31: Bavarian 33cl | I31: =SUM(B15:E15) -> 12012 | J31: =I31/3610 -> 3.3274238
A32: Jus de Citron (kg) | C32: =_xlfn.XLOOKUP(_xlfn.XLOOKUP(B8,Data!A:A,Data!B:B),Recettes!B:B,Recettes!E:E) -> 20.80384 | G32: Saft 75cl | I32: =G15+H15 -> 1110 | J32: =I32/1421 -> 0.78114004
A33: Grains (kg) | C33: =_xlfn.XLOOKUP(_xlfn.XLOOKUP(B8,Data!A:A,Data!B:B),Recettes!B:B,Recettes!F:F) -> 31.20576 | G33: Eau gazeuse 75cl | I33: =F15 -> 6 | J33: =I33/1421 -> 0.0042223786
A35: Volume de remplissage : | C35: =B17+400 -> 5200.96 | G35: Palette Europe | I35: =F17 -> 0 | J35: =I35/1421 -> 0
A36: Niveau de liquide : | C36: ='CUVE 1 et 2 Mesure'!G6 -> 268.996
A37: Pression sur le bulleur : | C37: 3 bars
A38: Température de cuve : | C38: 24°C
A40: Phase 2 : Filtration
A41: =A8 -> Produit :
A42: Volume filtré : | B42: =IF(ISNUMBER( SEARCH("Infusion",B8)), 0, (C35-200)*60%) -> 3000.576
A43: Volume final : | B43: =IF(ISNUMBER(SEARCH("infusion",B8)),0,_xlfn.XLOOKUP(B8,Data!E:E,Data!F:F)*'Fiche de production'!C35+B42) -> 3125.399
A44: Hauteur : | B44: ='CUVE 1 et 2 Mesure'!G13 -> 160.76995
A46: Phase 2 : Remplissage
A47: =A14 -> Quantité
A48: Volume total : | B48: =_xlfn.XLOOKUP(B8,Data!E:E,Data!F:F)*'Fiche de production'!C35+C35-400 -> 4925.783
A49: Hauteur : | B49: ='CUVE 1 et 2 Mesure'!G21 -> 251.45728
A51: IMPORTANT : la hauteur totale prend en compte l'ajout des jus de l'aromatisation
...

Sheet Recettes
A1: Quantité (L) | B1: ='Fiche de production'!C35 -> 5200.96
C3: Sucre (kg) | D3: Figues (kg) | E3: Jus de Citron (kg) | F3: Grains (kg)
B4: Infusion | C4: =B12*B1 -> 57.21056 | D4: =B1*B13 -> 41.60768 | E4: =B14*B1 -> 20.80384 | F4: =B15*B1 -> 41.60768
B5: Kéfir | C5: =B1*B21 -> 182.0336 | D5: =B1*B22 -> 83.21536 | E5: =B23*B1 -> 20.80384 | F5: =B24*B1 -> 31.20576
A10: Recette Eau
B11: Facteur 1L
A12: sucre blanc | B12: 0.011
A13: figues | B13: 0.008
A14: jus citron | B14: 0.004
A15: grain | B15: 0.008
A19: Recette Kefir
B20: Facteur 1L
A21: sucre blanc | B21: 0.035
A22: figues | B22: 0.016
A23: jus citron | B23: 0.004
A24: grain | B24: 0.006

Sheet Data
A1: Produit 1 | B1: Type | C1: DDM | E1: Ajouts de Jus / L | F1: pour 1L
A2: K. Original | B2: Kéfir | C2: 365 | E2: K. Original | F2: 0.004
A3: K. Menthe - Citron Vert | B3: Kéfir | C3: 365 | E3: K. Menthe - Citron Vert | F3: 0.008
A4: K. Gingembre | B4: Kéfir | C4: 365 | E4: K. Gingembre | F4: 0.024
A5: K. Pamplemousse | B5: Kéfir | C5: 365 | E5: K. Pamplemousse | F5: =0.08+0.0012+0.004 -> 0.0852
A6: K. Mangue - Passion | B6: Kéfir | C6: 365 | E6: K. Mangue - Passion | F6: 0.034
A7: Infusion Menthe Poivrée | B7: infusion | C7: 365 | E7: Infusion Menthe Poivrée | F7: 0.0047
A8: Infusion Mélisse | B8: infusion | C8: 365 | E8: Infusion Mélisse | F8: 0.007
A9: Infusion Zest d'agrumes | B9: infusion | C9: 365 | E9: Infusion Zest d'agrumes | F9: 0
A10: K. Pêche | B10: Kéfir | C10: 365 | E10: K. Pêche | F10: 0.0158
A11: Autre : | C11: 365

Sheet CUVE 1 et 2 Mesure
A1: Volume (en L) | B1: Regle (en cm) | C1: Palier de Volume | D1: Palier de cm | F1: Volume de remplissage | G1: ='Fiche de production'!C35 -> 5200.96
A2: 0 | B2: 0 | C2: 0 | F2: Limite Basse | G2: {=MAX(IF(A:A<=G1,A:A))} -> 5200
A3: 100 | B3: 6.5 | C3: =A3-A2 -> 100 | D3: =B3-B2 -> 6.5 | F3: Limite Haute | G3: {=MIN(IF(A:A>=G1,A:A))} -> 5250
A4: 150 | B4: 10 | C4: =A4-A3 -> 50 | D4: =B4-B3 -> 3.5 | F4: Hauteur limite Basse | G4: =_xlfn.XLOOKUP(G2,A:A,B:B) -> 268.9
A5: 200 | B5: 13.3 | C5: =A5-A4 -> 50 | D5: =B5-B4 -> 3.3 | F5: Hauteur limite Haute | G5: =_xlfn.XLOOKUP(G3,A:A,B:B) -> 273.9
A6: 250 | B6: 16.2 | C6: =A6-A5 -> 50 | D6: =B6-B5 -> 2.9 | F6: HAUTEUR CIBLE | G6: =G4+(G1-G2)*(G5-G4)/(G3-G2) -> 268.996
A7: 300.5 | B7: 19 | C7: 50 | D7: =B7-B6 -> 2.8
A8: 350.5 | B8: 21.7 | C8: =A8-A7 -> 50 | D8: =B8-B7 -> 2.7 | F8: Valeur recherchée Produit Post Filtration | G8: ='Fiche de production'!B43 -> 3125.399
A9: 400.5 | B9: 24.3 | C9: =A9-A8 -> 50 | D9: =B9-B8 -> 2.6 | F9: Limite Basse | G9: {=MAX(IF(A:A<=G8,A:A))} -> 3000
A10: 451.5 | B10: 26.9 | C10: =A10-A9 -> 51 | D10: =B10-B9 -> 2.6 | F10: Limite Haute | G10: {=MIN(IF(A:A>=G8,A:A))} -> 3250
A11: 501.5 | B11: 29.4 | C11: =A11-A10 -> 50 | D11: =B11-B10 -> 2.5 | F11: Hauteur limite Basse | G11: =_xlfn.XLOOKUP(G9,A:A,B:B) -> 154.5
A12: 551.5 | B12: 32 | C12: =A12-A11 -> 50 | D12: =B12-B11 -> 2.6 | F12: Hauteur limite Haute | G12: =_xlfn.XLOOKUP(G10,A:A,B:B) -> 167
A13: 600 | B13: 34.5 | C13: =A13-A12 -> 48.5 | D13: =B13-B12 -> 2.5 | F13: HAUTEUR CIBLE | G13: =IFERROR((G11+(G8-G9)*(G12-G11)/(G10-G9)),0) -> 160.76995
A14: 750 | B14: =B13+D14 -> 42 | C14: =A14-A13 -> 150 | D14: 7.5
A15: 1000 | B15: =B14+D15 -> 54.5 | C15: =A15-A14 -> 250 | D15: 12.5
A16: 1250 | B16: =B15+50/4 -> 67 | C16: =A16-A15 -> 250 | D16: =B16-B15 -> 12.5 | F16: Valeur recherchée Produit Cuve pleine | G16: ='Fiche de production'!B48 -> 4925.783
A17: 1500 | B17: =B16+50/4 -> 79.5 | C17: =A17-A16 -> 250 | D17: =B17-B16 -> 12.5 | F17: Limite Basse | G17: {=MAX(IF(A:A<=G16,A:A))} -> 4899.5
A18: 1750 | B18: =B17+50/4 -> 92 | C18: =A18-A17 -> 250 | D18: =B18-B17 -> 12.5 | F18: Limite Haute | G18: {=MIN(IF(A:A>=G16,A:A))} -> 4950
A19: 2000 | B19: =B18+50/4 -> 104.5 | C19: =A19-A18 -> 250 | D19: =B19-B18 -> 12.5 | F19: Hauteur limite Basse | G19: =_xlfn.XLOOKUP(G17,A:A,B:B) -> 250
A20: 2250 | B20: =B19+50/4 -> 117 | C20: =A20-A19 -> 250 | D20: =B20-B19 -> 12.5 | F20: Hauteur limite Haute | G20: =_xlfn.XLOOKUP(G18,A:A,B:B) -> 252.8
A21: 2500 | B21: =B20+50/4 -> 129.5 | C21: =A21-A20 -> 250 | D21: =B21-B20 -> 12.5 | F21: HAUTEUR CIBLE | G21: =G19+(G16-G17)*(G20-G19)/(G18-G17) -> 251.45728
A22: 2750 | B22: =B21+50/4 -> 142 | C22: =A22-A21 -> 250 | D22: =B22-B21 -> 12.5
A23: 3000 | B23: =B22+50/4 -> 154.5 | C23: =A23-A22 -> 250 | D23: =B23-B22 -> 12.5
A24: 3250 | B24: =B23+50/4 -> 167 | C24: =A24-A23 -> 250 | D24: =B24-B23 -> 12.5
A25: 3500 | B25: =B24+50/4 -> 179.5 | C25: =A25-A24 -> 250 | D25: =B25-B24 -> 12.5
A26: 3750 | B26: =B25+50/4 -> 192 | C26: =A26-A25 -> 250 | D26: =B26-B25 -> 12.5
A27: 4000 | B27: =B26+50/4 -> 204.5 | C27: =A27-A26 -> 250 | D27: =B27-B26 -> 12.5
A28: 4250 | B28: =B27+50/4 -> 217 | C28: =A28-A27 -> 250 | D28: =B28-B27 -> 12.5
A29: 4500 | B29: =B28+50/4 -> 229.5 | C29: =A29-A28 -> 250 | D29: =B29-B28 -> 12.5
A30: 4600 | B30: =D30+B29 -> 234.5 | C30: 100 | D30: =100*12.5/250 -> 5
A31: 4650 | B31: =B30+D31 -> 237 | C31: =C13 -> 48.5 | D31: =D13 -> 2.5
A32: 4700 | B32: =B31+D32 -> 239.6 | C32: =C12 -> 50 | D32: =D12 -> 2.6
A33: 4750 | B33: =B32+D33 -> 242.1 | C33: =C11 -> 50 | D33: =D11 -> 2.5
A34: 4799.5 | B34: =B33+D34 -> 244.7 | C34: =C10 -> 51 | D34: =D10 -> 2.6
A35: 4849.5 | B35: =B34+D35 -> 247.3 | C35: =C9 -> 50 | D35: =D9 -> 2.6
A36: 4899.5 | B36: =B35+D36 -> 250 | C36: =C8 -> 50 | D36: =D8 -> 2.7
A37: 4950 | B37: =B36+D37 -> 252.8 | C37: =C7 -> 50 | D37: =D7 -> 2.8
A38: 5000 | B38: =B37+D38 -> 255.7 | C38: =C6 -> 50 | D38: =D6 -> 2.9
A39: 5050 | B39: =B38+D39 -> 258.7 | C39: =C5 -> 50 | D39: 3
A40: 5100 | B40: =B39+D40 -> 261.9 | C40: =C4 -> 50 | D40: 3.2
...
